Workbook

Sheet Posted Sales Invoices
A1: No. | B1: Customer No. | C1: Customer Name | D1: Posting Date | E1: Order No. | F1: Amount | G1: Location Code | H1: No. Printed | I1: Delivery Date | J1: Requested Delivery Date | K1: Shipping Agent Code | L1: Closed | M1: Canceled | N1: Corrective
A2: PS-INV229528 | B2: 13257 | C2: PFG Springfield MA | D2: 46197 | E2: S-ORD229528 | F2: 31928.4 | G2: NR-BRHL-FG | H2: 1 | I2: 46197 | J2: 46197 | K2: RT 21 | L2: =FALSE() -> FALSE | M2: =FALSE() -> FALSE | N2: =FALSE() -> FALSE
A3: PS-INV228483 | B3: 10540-03 | C3: PFG Louisville TN | D3: 46197 | E3: S-ORD228483 | F3: 24442.84 | G3: NR-BRHL-FG | H3: 2 | I3: 46197 | J3: 46197 | K3: RT 21 | L3: =FALSE() -> FALSE | M3: =FALSE() -> FALSE | N3: =FALSE() -> FALSE
A4: PS-INV227629 | B4: 10719-4 | C4: US Foods - Columbia/Lexington | D4: 46197 | E4: S-ORD227629 | F4: 6665 | G4: NR-BRHL-FG | H4: 2 | I4: 46197 | J4: 46197 | K4: RT 21 | L4: =FALSE() -> FALSE | M4: =FALSE() -> FALSE | N4: =FALSE() -> FALSE
A5: PS-INV227718 | B5: 20334 | C5: Sysco Atlanta | D5: 46196 | E5: S-ORD227718 | F5: 22383.16 | G5: NR-BRHL-FG | H5: 0 | I5: 46196 | J5: 46196 | K5: RT 21 | L5: =FALSE() -> FALSE | M5: =FALSE() -> FALSE | N5: =FALSE() -> FALSE
A6: PS-INV227566 | B6: 10511 | C6: Sysco Nashville, LLC | D6: 46196 | E6: S-ORD227566 | F6: 30238.48 | G6: NR-BRHL-FG | H6: 0 | I6: 46196 | J6: 46196 | K6: RT 21 | L6: =FALSE() -> FALSE | M6: =FALSE() -> FALSE | N6: =FALSE() -> FALSE
A7: PS-INV225932 | B7: 10719-13 | C7: US Foods - Montgomery | D7: 46196 | E7: S-ORD225932 | F7: 21862.4 | G7: NR-BRHL-FG | H7: 0 | I7: 46196 | J7: 46196 | K7: RT 21 | L7: =FALSE() -> FALSE | M7: =FALSE() -> FALSE | N7: =FALSE() -> FALSE
A8: PS-INV227180 | B8: 10899 | C8: Wood Fruitticher Grocery Co. | D8: 46195 | E8: S-ORD227180 | F8: 27636.68 | G8: NR-BRHL-FG | H8: 2 | I8: 46195 | J8: 46195 | K8: RT 21 | L8: =FALSE() -> FALSE | M8: =FALSE() -> FALSE | N8: =FALSE() -> FALSE
A9: PS-INV226973 | B9: 12438 | C9: SGC Foodservice | D9: 46195 | E9: S-ORD226973 | F9: 30466.24 | G9: NR-BRHL-FG | H9: 2 | I9: 46195 | J9: 46195 | K9: RT 21 | L9: =FALSE() -> FALSE | M9: =FALSE() -> FALSE | N9: =FALSE() -> FALSE
A10: PS-INV225785 | B10: 10549 | C10: PFG Nashville TN | D10: 46195 | E10: S-ORD225785 | F10: 2229 | G10: NR-BRHL-FG | H10: 1 | I10: 46195 | J10: 46195 | K10: RT 21 | L10: =FALSE() -> FALSE | M10: =FALSE() -> FALSE | N10: =FALSE() -> FALSE
A11: PS-INV226637 | B11: 10540-03 | C11: PFG Louisville TN | D11: 46191 | E11: S-ORD226637 | F11: 29305.64 | G11: NR-BRHL-FG | H11: 0 | I11: 46191 | J11: 46191 | K11: RT 21 | L11: =FALSE() -> FALSE | M11: =FALSE() -> FALSE | N11: =FALSE() -> FALSE
A12: PS-INV226049 | B12: 11005 | C12: Dot Foods Inc. | D12: 46191 | E12: S-ORD226049 | F12: 21388.8 | G12: NR-BRHL-FG | H12: 0 | I12: 46191 | J12: 46191 | K12: RT 21 | L12: =FALSE() -> FALSE | M12: =FALSE() -> FALSE | N12: =FALSE() -> FALSE
A13: PS-INV225952 | B13: 10700 | C13: Gordon Food Service - Douglas | D13: 46191 | E13: S-ORD225952 | F13: 30204.24 | G13: NR-BRHL-FG | H13: 0 | I13: 46191 | J13: 46191 | K13: RT 21 | L13: =FALSE() -> FALSE | M13: =FALSE() -> FALSE | N13: =FALSE() -> FALSE
... A30: PS-INV224543 | B30: 10540-03 | C30: PFG Louisville TN | D30: 46183 | E30: S-ORD224543 | F30: 22521.4 | G30: NR-BRHL-FG | H30: 2 | I30: 46183 | J30: 46183 | K30: RT 21 | L30: =FALSE() -> FALSE | M30: =FALSE() -> FALSE | N30: =FALSE() -> FALSE
A31: PS-INV223472 | B31: 10899 | C31: Wood Fruitticher Grocery Co. | D31: 46183 | E31: S-ORD223472 | F31: 26113.6 | G31: NR-BRHL-FG | H31: 2 | I31: 46183 | J31: 46183 | K31: RT 21 | L31: =TRUE() -> TRUE | M31: =FALSE() -> FALSE | N31: =FALSE() -> FALSE
A32: PS-INV223459 | B32: 10540-01 | C32: PFG Johnson City TN | D32: 46183 | E32: S-ORD223459 | F32: 12979.44 | G32: NR-BRHL-FG | H32: 2 | I32: 46183 | J32: 46183 | K32: RT 21 | L32: =FALSE() -> FALSE | M32: =FALSE() -> FALSE | N32: =FALSE() -> FALSE
A33: PS-INV222984 | B33: 12989 | C33: Sysco Little Rock Arkansas | D33: 46183 | E33: S-ORD222984 | F33: 10694.6 | G33: NR-BRHL-FG | H33: 1 | I33: 46183 | J33: 46183 | K33: RT 21 | L33: =FALSE() -> FALSE | M33: =FALSE() -> FALSE | N33: =FALSE() -> FALSE
A34: PS-INV222981 | B34: 12988 | C34: Sysco Norman OK | D34: 46183 | E34: S-ORD222981 | F34: 24920 | G34: NR-BRHL-FG | H34: 2 | I34: 46183 | J34: 46183 | K34: RT 21 | L34: =FALSE() -> FALSE | M34: =FALSE() -> FALSE | N34: =FALSE() -> FALSE
A35: PS-INV223468 | B35: 11005 | C35: Dot Foods Inc. | D35: 46182 | E35: S-ORD223468 | F35: 17111.04 | G35: NR-BRHL-FG | H35: 1 | I35: 46182 | J35: 46182 | K35: RT 21 | L35: =FALSE() -> FALSE | M35: =FALSE() -> FALSE | N35: =FALSE() -> FALSE
A36: PS-INV223450 | B36: 13128 | C36: Gordon Food Service - Shepherdsville | D36: 46182 | E36: S-ORD223450 | F36: 31873.44 | G36: NR-BRHL-FG | H36: 1 | I36: 46182 | J36: 46182 | K36: RT 21 | L36: =FALSE() -> FALSE | M36: =FALSE() -> FALSE | N36: =FALSE() -> FALSE
A37: PS-INV223008 | B37: 12438 | C37: SGC Foodservice | D37: 46182 | E37: S-ORD223008 | F37: 4545.12 | G37: NR-BRHL-FG | H37: 2 | I37: 46182 | J37: 46182 | K37: RT 21 | L37: =FALSE() -> FALSE | M37: =FALSE() -> FALSE | N37: =FALSE() -> FALSE
A38: PS-INV221682 | B38: 10547 | C38: PFG Hale TN | D38: 46182 | E38: S-ORD221682 | F38: 23098 | G38: NR-BRHL-FG | H38: 3 | I38: 46182 | J38: 46182 | K38: RT 21 | L38: =FALSE() -> FALSE | M38: =FALSE() -> FALSE | N38: =FALSE() -> FALSE
A39: PS-INV222006 | B39: 10719-2 | C39: US Foods - Fairburn | D39: 46181 | E39: S-ORD222006 | F39: 15686.28 | G39: NR-BRHL-FG | H39: 2 | I39: 46181 | J39: 46181 | K39: RT 21 | L39: =FALSE() -> FALSE | M39: =FALSE() -> FALSE | N39: =FALSE() -> FALSE
A40: PS-INV222001 | B40: 20334 | C40: Sysco Atlanta | D40: 46178 | E40: S-ORD222001 | F40: 16114.8 | G40: NR-BRHL-FG | H40: 1 | I40: 46178 | J40: 46178 | K40: RT 21 | L40: =FALSE() -> FALSE | M40: =FALSE() -> FALSE | N40: =FALSE() -> FALSE
A41: PS-INV221360 | B41: 10805 | C41: Sysco Jacksonville | D41: 46177 | E41: S-ORD221360 | F41: 18447.6 | G41: NR-BRHL-FG | H41: 2 | I41: 46177 | J41: 46177 | K41: RT 21 | L41: =FALSE() -> FALSE | M41: =FALSE() -> FALSE | N41: =FALSE() -> FALSE
A42: PS-INV223466 | B42: X10540-3 | C42: PFG Pittsburgh PA | D42: 46176 | E42: S-ORD223466 | F42: 17388 | G42: NR-BRHL-FG | H42: 1 | I42: 46176 | J42: 46176 | K42: RT 21 | L42: =FALSE() -> FALSE | M42: =FALSE() -> FALSE | N42: =FALSE() -> FALSE
A43: PS-INV221683 | B43: 13128 | C43: Gordon Food Service - Shepherdsville | D43: 46176 | E43: S-ORD221683 | F43: 32119.2 | G43: NR-BRHL-FG | H43: 1 | I43: 46176 | J43: 46176 | K43: RT 21 | L43: =FALSE() -> FALSE | M43: =FALSE() -> FALSE | N43: =FALSE() -> FALSE
... A54: PS-INV217270 | B54: 10700 | C54: Gordon Food Service - Douglas | D54: 46174 | E54: S-ORD217270 | F54: 28488.62 | G54: NR-BRHL-FG | H54: 2 | I54: 46174 | J54: 46174 | K54: RT 21 | L54: =FALSE() -> FALSE | M54: =FALSE() -> FALSE | N54: =FALSE() -> FALSE
A55: PS-INV220965 | B55: 12438 | C55: SGC Foodservice | D55: 46170 | E55: S-ORD220965 | F55: 30060.8 | G55: NR-BRHL-FG | H55: 2 | I55: 46170 | J55: 46170 | K55: RT 21 | L55: =TRUE() -> TRUE | M55: =FALSE() -> FALSE | N55: =FALSE() -> FALSE
A56: PS-INV220865 | B56: 10540-03 | C56: PFG Louisville TN | D56: 46170 | E56: S-ORD220865 | F56: 24209.52 | G56: NR-BRHL-FG | H56: 2 | I56: 46170 | J56: 46170 | K56: RT 21 | L56: =FALSE() -> FALSE | M56: =FALSE() -> FALSE | N56: =FALSE() -> FALSE
A57: PS-INV218854 | B57: 11005 | C57: Dot Foods Inc. | D57: 46170 | E57: S-ORD218854 | F57: 13902.72 | G57: NR-BRHL-FG | H57: 1 | I57: 46170 | J57: 46170 | K57: RT 21 | L57: =FALSE() -> FALSE | M57: =FALSE() -> FALSE | N57: =FALSE() -> FALSE
A58: PS-INV218758 | B58: 12988 | C58: Sysco Norman OK | D58: 46170 | E58: S-ORD218758 | F58: 26852 | G58: NR-BRHL-FG | H58: 2 | I58: 46170 | J58: 46170 | K58: RT 21 | L58: =FALSE() -> FALSE | M58: =FALSE() -> FALSE | N58: =FALSE() -> FALSE
A59: PS-INV219174 | B59: Z10700 | C59: Sysco-Charlotte | D59: 46169 | E59: S-ORD219174 | F59: 24873.36 | G59: NR-BRHL-FG | H59: 2 | I59: 46169 | J59: 46169 | K59: RT 21 | L59: =FALSE() -> FALSE | M59: =FALSE() -> FALSE | N59: =FALSE() -> FALSE
A60: PS-INV218773 | B60: 12692 | C60: United Food Service | D60: 46169 | E60: S-ORD218773 | F60: 8477 | G60: NR-BRHL-FG | H60: 0 | I60: 46169 | J60: 46169 | K60: RT 21 | L60: =FALSE() -> FALSE | M60: =FALSE() -> FALSE | N60: =FALSE() -> FALSE
A61: PS-INV219516 | B61: 10511 | C61: Sysco Nashville, LLC | D61: 46168 | E61: S-ORD219516 | F61: 20374.56 | G61: NR-BRHL-FG | H61: 4 | I61: 46168 | J61: 46168 | K61: RT 21 | L61: =FALSE() -> FALSE | M61: =FALSE() -> FALSE | N61: =FALSE() -> FALSE
A62: PS-INV218015 | B62: 10549 | C62: PFG Nashville TN | D62: 46168 | E62: S-ORD218015 | F62: 1854 | G62: NR-BRHL-FG | H62: 1 | I62: 46168 | J62: 46168 | K62: RT 21 | L62: =FALSE() -> FALSE | M62: =FALSE() -> FALSE | N62: =FALSE() -> FALSE
A63: PS-INV219937 | B63: 20334 | C63: Sysco Atlanta | D63: 46167 | E63: S-ORD219937 | F63: 21973.04 | G63: NR-BRHL-FG | H63: 1 | I63: 46171 | J63: 46171 | K63: RT 21 | L63: =FALSE() -> FALSE | M63: =FALSE() -> FALSE | N63: =FALSE() -> FALSE
A64: PS-INV218061 | B64: 13128 | C64: Gordon Food Service - Shepherdsville | D64: 46167 | E64: S-ORD218061 | F64: 21452.48 | G64: NR-BRHL-FG | H64: 1 | I64: 46167 | J64: 46167 | K64: RT 21 | L64: =FALSE() -> FALSE | M64: =FALSE() -> FALSE | N64: =FALSE() -> FALSE
A65: PS-INV217295 | B65: X10540-3 | C65: PFG Pittsburgh PA | D65: 46167 | E65: S-ORD217295 | F65: 30850.4 | G65: NR-BRHL-FG | H65: 1 | I65: 46167 | J65: 46167 | K65: RT 21 | L65: =FALSE() -> FALSE | M65: =FALSE() -> FALSE | N65: =FALSE() -> FALSE
A66: PS-INV218249 | B66: 20334 | C66: Sysco Atlanta | D66: 46164 | E66: S-ORD218249 | F66: 13426.16 | G66: NR-BRHL-FG | H66: 2 | I66: 46164 | J66: 46164 | K66: RT 21 | L66: =TRUE() -> TRUE | M66: =FALSE() -> FALSE | N66: =FALSE() -> FALSE
...

Sheet Posted Sales Invoice Lines
A1: Document No. | B1: Sell-to Customer No. | C1: Sell-to Customer Name | D1: Type | E1: No. | F1: Description | G1: Posting Date | H1: Gen. Bus. Posting Group | I1: Gen. Prod. Posting Group | J1: Pc Code | K1: Dept Code | L1: Quantity | M1: Unit of Measure Code | N1: Unit Price Excl. Tax | O1: Amount | P1: Amount Including Tax | Q1: Line Discount %
A2: PS-INV173271 | B2: 10719-6 | C2: US Foods - Alcoa TN. | D2: Item | E2: F53094 | F2: Cs. 6" Italian 12-6pks | G2: 46027 | I2: FG-DIST | J2: EBC | L2: 28 | M2: EA | N2: 35 | O2: 980 | P2: 980 | Q2: 0
A3: PS-INV173271 | B3: 10719-6 | C3: US Foods - Alcoa TN. | D3: Item | E3: F51136 | F3: Cs. Texas Toast 1" 12lvs | G3: 46027 | I3: FG-DIST | J3: EBC | L3: 84 | M3: EA | N3: 40.12 | O3: 3370.08 | P3: 3370.08 | Q3: 0
A4: PS-INV173271 | B4: 10719-6 | C4: US Foods - Alcoa TN. | D4: Item | E4: F51004 | F4: Cs. Rye 5/8" 8lvs | G4: 46027 | I4: FG-DIST | J4: EBC | L4: 8 | M4: EA | N4: 42.03 | O4: 336.24 | P4: 336.24 | Q4: 0
A5: PS-INV173271 | B5: 10719-6 | C5: US Foods - Alcoa TN. | D5: Item | E5: F53025 | F5: Cs. Sesame Challah Kaiser 8-12pk | G5: 46027 | I5: FG-DIST | J5: EBC | L5: 308 | M5: EA | N5: 39 | O5: 12012 | P5: 12012 | Q5: 0
A6: PS-INV173271 | B6: 10719-6 | C6: US Foods - Alcoa TN. | D6: Item | E6: F53087 | F6: Cs. 3.5" Challah Bun 8-12 pk | G6: 46027 | I6: FG-DIST | J6: EBC | L6: 28 | M6: EA | N6: 36.24 | O6: 1014.72 | P6: 1014.72 | Q6: 0
A7: PS-INV173271 | B7: 10719-6 | C7: US Foods - Alcoa TN. | D7: Item | E7: F51066 | F7: Cs. Honey Wheat 3/4" 8lvs | G7: 46027 | I7: FG-DIST | J7: EBC | L7: 14 | M7: EA | N7: 35.21 | O7: 492.94 | P7: 492.94 | Q7: 0
A8: PS-INV173271 | B8: 10719-6 | C8: US Foods - Alcoa TN. | D8: Item | E8: F53001 | F8: Cs. 4" Brioche Bun 8-12pk | G8: 46027 | I8: FG-DIST | J8: EBC | L8: 140 | M8: EA | N8: 45.49 | O8: 6368.6 | P8: 6368.6 | Q8: 0
A9: PS-INV173271 | B9: 10719-6 | C9: US Foods - Alcoa TN. | D9: Item | E9: F530501 | F9: Cs. 4.5" Challah Kaiser 6-12pk | G9: 46027 | I9: FG-DIST | J9: EBC | L9: 28 | M9: EA | N9: 37.02 | O9: 1036.56 | P9: 1036.56 | Q9: 0
A10: PS-INV173271 | B10: 10719-6 | C10: US Foods - Alcoa TN. | D10: Item | E10: F51084 | F10: Cs. Wheatberry Hearth | G10: 46027 | I10: FG-DIST | J10: EBC | L10: 4 | M10: EA | N10: 52.47 | O10: 209.88 | P10: 209.88 | Q10: 0
A11: PS-INV173271 | B11: 10719-6 | C11: US Foods - Alcoa TN. | D11: Item | E11: F51024 | F11: Cs. Marble Rye 5/8" 8lvs | G11: 46027 | I11: FG-DIST | J11: EBC | L11: 4 | M11: EA | N11: 54 | O11: 216 | P11: 216 | Q11: 0
A12: PS-INV173271 | B12: 10719-6 | C12: US Foods - Alcoa TN. | D12: Item | E12: F51034 | F12: Cs. Sour Dough Hearth 5/8" 8lvs | G12: 46027 | I12: FG-DIST | J12: EBC | L12: 8 | M12: EA | N12: 43.2 | O12: 345.6 | P12: 345.6 | Q12: 0
A13: PS-INV173271 | B13: 10719-6 | C13: US Foods - Alcoa TN. | D13: Item | E13: F51157 | F13: Cs. Challah Hearth 7/8" 8lvs | G13: 46027 | I13: FG-DIST | J13: EBC | L13: 28 | M13: EA | N13: 44.15 | O13: 1236.2 | P13: 1236.2 | Q13: 0
... A86: PS-INV178030 | B86: 12989 | C86: Sysco Little Rock Arkansas | D86: Item | E86: F53115 | F86: Cs. 7" French Unsliced 12-6pk | G86: 46037 | I86: FG-DIST | J86: EBC | L86: 224 | M86: EA | N86: 35 | O86: 7840 | P86: 7840 | Q86: 0
A87: PS-INV178033 | B87: 13092 | C87: Sysco WEST COAST | D87: Item | E87: F51137 | F87: Cs. Texas Toast 3/4" 12lvs | G87: 46035 | H87: DOMESTIC | I87: FG-DIST | J87: EBC | L87: 336 | M87: EA | N87: 35 | O87: 11760 | P87: 11760 | Q87: 0
A88: PS-INV178033 | B88: 13092 | C88: Sysco WEST COAST | D88: Item | E88: F530491 | F88: Cs. 4.5 Brioche Bun 6-12pk | G88: 46035 | H88: DOMESTIC | I88: FG-DIST | J88: EBC | L88: 112 | M88: EA | N88: 39.65 | O88: 4440.8 | P88: 4440.8 | Q88: 0
A89: PS-INV178270 | B89: 10540-02 | C89: PFG Valdosta GA | D89: Item | E89: F53001 | F89: Cs. 4" Brioche Bun 8-12pk | G89: 46036 | I89: FG-DIST | J89: EBC | L89: 40 | M89: EA | N89: 42.6 | O89: 1704 | P89: 1704 | Q89: 0
A90: PS-INV178270 | B90: 10540-02 | C90: PFG Valdosta GA | D90: Item | E90: F54301 | F90: Cs. Potato Roll Sliced 12-16pk | G90: 46036 | I90: FG-DIST | J90: EBC | L90: 36 | M90: EA | N90: 41.15 | O90: 1481.4 | P90: 1481.4 | Q90: 0
A91: PS-INV178270 | B91: 10540-02 | C91: PFG Valdosta GA | D91: Item | E91: F51000 | F91: Cs. Rye Bread 8lvs | G91: 46036 | I91: FG-DIST | J91: EBC | L91: 4 | M91: EA | N91: 41.6 | O91: 166.4 | P91: 166.4 | Q91: 0
A92: PS-INV178288 | B92: 11394 | C92: La Cosecha Food Service | D92: Item | E92: F53003 | F92: Cs. 4" Unseeded Challah Bun 8-12pk | G92: 46036 | I92: FG-DIST | J92: EBC | L92: 30 | M92: EA | N92: 30.32 | O92: 909.6 | P92: 909.6 | Q92: 0
A93: PS-INV178288 | B93: 11394 | C93: La Cosecha Food Service | D93: Item | E93: F530401 | F93: Cs. 4.5" Sesame 6-12pk | G93: 46036 | I93: FG-DIST | J93: EBC | L93: 30 | M93: EA | N93: 34.18 | O93: 1025.4 | P93: 1025.4 | Q93: 0
A94: PS-INV178335 | B94: 10805 | C94: Sysco Jacksonville | D94: Item | E94: F53100 | F94: Cs. Hot Dog pl/sl 12-8pk | G94: 46037 | I94: FG-DIST | J94: EBC | L94: 4 | M94: EA | N94: 36.6 | O94: 146.4 | P94: 146.4 | Q94: 0
A95: PS-INV178335 | B95: 10805 | C95: Sysco Jacksonville | D95: Item | E95: F53001 | F95: Cs. 4" Brioche Bun 8-12pk | G95: 46037 | I95: FG-DIST | J95: EBC | L95: 28 | M95: EA | N95: 50.6 | O95: 1416.8 | P95: 1416.8 | Q95: 0
A96: PS-INV178335 | B96: 10805 | C96: Sysco Jacksonville | D96: Item | E96: F53003 | F96: Cs. 4" Unseeded Challah Bun 8-12pk | G96: 46037 | I96: FG-DIST | J96: EBC | L96: 252 | M96: EA | N96: 40.8 | O96: 10281.6 | P96: 10281.6 | Q96: 0
A97: PS-INV178335 | B97: 10805 | C97: Sysco Jacksonville | D97: Item | E97: F51137 | F97: Cs. Texas Toast 3/4" 12lvs | G97: 46037 | I97: FG-DIST | J97: EBC | L97: 140 | M97: EA | N97: 39.9 | O97: 5586 | P97: 5586 | Q97: 0
A98: PS-INV178335 | B98: 10805 | C98: Sysco Jacksonville | D98: Item | E98: F56251 | F98: Cs. Challah Sliders Sliced 18-12pks | G98: 46037 | I98: FG-DIST | J98: EBC | L98: 28 | M98: EA | N98: 42.35 | O98: 1185.8 | P98: 1185.8 | Q98: 0
A99: PS-INV178998 | B99: 10899 | C99: Wood Fruitticher Grocery Co. | D99: Item | E99: F54301 | F99: Cs. Potato Roll Sliced 12-16pk | G99: 46027 | I99: FG-DIST | J99: EBC | L99: 12 | M99: EA | N99: 40.1 | O99: 481.2 | P99: 481.2 | Q99: 0
A100: PS-INV178998 | B100: 10899 | C100: Wood Fruitticher Grocery Co. | D100: Item | E100: F53115 | F100: Cs. 7" French Unsliced 12-6pk | G100: 46027 | I100: FG-DIST | J100: EBC | L100: 12 | M100: EA | N100: 28.88 | O100: 346.56 | P100: 346.56 | Q100: 0
... A116: PS-INV179010 | B116: 20334 | C116: Sysco Atlanta | D116: Item | E116: F53140 | F116: Cs. Knuckies 8" White 12-6pk | G116: 46037 | I116: FG-DIST | J116: EBC | L116: 20 | M116: EA | N116: 41 | O116: 820 | P116: 820 | Q116: 0
A117: PS-INV179035 | B117: 13128 | C117: Gordon Food Service - Shepherdsville | D117: Item | E117: F51084 | F117: Cs. Wheatberry Hearth | G117: 46037 | H117: DOMESTIC | I117: FG-DIST | J117: EBC | L117: 48 | M117: EA | N117: 33.3 | O117: 1598.4 | P117: 1598.4 | Q117: 0
A118: PS-INV179035 | B118: 13128 | C118: Gordon Food Service - Shepherdsville | D118: Item | E118: F53001 | F118: Cs. 4" Brioche Bun 8-12pk | G118: 46037 | H118: DOMESTIC | I118: FG-DIST | J118: EBC | L118: 256 | M118: EA | N118: 36.82 | O118: 9425.92 | P118: 9425.92 | Q118: 0
A119: PS-INV179035 | B119: 13128 | C119: Gordon Food Service - Shepherdsville | D119: Item | E119: F51114 | F119: Cs. Old Fashioned Hearth 5/8" 8lvs | G119: 46037 | H119: DOMESTIC | I119: FG-DIST | J119: EBC | L119: 112 | M119: EA | N119: 39.7 | O119: 4446.4 | P119: 4446.4 | Q119: 0
A120: PS-INV179035 | B120: 13128 | C120: Gordon Food Service - Shepherdsville | D120: Item | E120: F56251 | F120: Cs. Challah Sliders Sliced 18-12pks | G120: 46037 | H120: DOMESTIC | I120: FG-DIST | J120: EBC | L120: 400 | M120: EA | N120: 39.7 | O120: 15880 | P120: 15880 | Q120: 0
A121: PS-INV179062 | B121: 10719-2 | C121: US Foods - Fairburn | D121: Item | E121: F53005 | F121: Cs. 4" Gourmet PDS Bun 8-12pk | G121: 46041 | I121: FG-DIST | J121: EBC | L121: 52 | M121: EA | N121: 40.11 | O121: 2085.72 | P121: 2085.72 | Q121: 0
A122: PS-INV179062 | B122: 10719-2 | C122: US Foods - Fairburn | D122: Item | E122: F56560 | F122: Gluten Free 3.5" Hamburger 36ct | G122: 46041 | I122: FG-DIST | J122: EBC | L122: 12 | M122: EA | N122: 48.57 | O122: 582.84 | P122: 582.84 | Q122: 0
A123: PS-INV179062 | B123: 10719-2 | C123: US Foods - Fairburn | D123: Item | E123: F53010 | F123: Cs. Onion Roll 8-12pk | G123: 46041 | I123: FG-DIST | J123: EBC | L123: 32 | M123: EA | N123: 40.85 | O123: 1307.2 | P123: 1307.2 | Q123: 0
A124: PS-INV179062 | B124: 10719-2 | C124: US Foods - Fairburn | D124: Item | E124: F53122 | F124: Cs. 8" Italian Hinged 12-6pk | G124: 46041 | I124: FG-DIST | J124: EBC | L124: 116 | M124: EA | N124: 40.9 | O124: 4744.4 | P124: 4744.4 | Q124: 0
A125: PS-INV179062 | B125: 10719-2 | C125: US Foods - Fairburn | D125: Item | E125: F53003 | F125: Cs. 4" Unseeded Challah Bun 8-12pk | G125: 46041 | I125: FG-DIST | J125: EBC | L125: 72 | M125: EA | N125: 38.08 | O125: 2741.76 | P125: 2741.76 | Q125: 0
A126: PS-INV179062 | B126: 10719-2 | C126: US Foods - Fairburn | D126: Item | E126: F53024 | F126: Cs. 4" Challah Kaiser 8-12pk | G126: 46041 | I126: FG-DIST | J126: EBC | L126: 60 | M126: EA | N126: 40.22 | O126: 2413.2 | P126: 2413.2 | Q126: 0
A127: PS-INV179701 | B127: 10540-03 | C127: PFG Louisville TN | D127: Item | E127: F530501 | F127: Cs. 4.5" Challah Kaiser 6-12pk | G127: 46037 | I127: FG-DIST | J127: EBC | L127: 28 | M127: EA | N127: 38.3 | O127: 1072.4 | P127: 1072.4 | Q127: 0
...

Sheet Combined Invoices & Lines
A1: Document No. | B1: Sell-to Customer No. | C1: Sell-to Customer Name | D1: No. | E1: Description | F1: Posting Date | G1: Quantity | H1: Unit Price Excl. Tax | I1: Amount
A2: ='Posted Sales Invoice Lines'!A2 -> PS-INV173271 | B2: ='Posted Sales Invoice Lines'!B2 -> 10719-6 | C2: ='Posted Sales Invoice Lines'!C2 -> US Foods - Alcoa TN. | D2: ='Posted Sales Invoice Lines'!E2 -> F53094 | E2: ='Posted Sales Invoice Lines'!F2 -> Cs. 6" Italian 12-6pks | F2: ='Posted Sales Invoice Lines'!G2 -> 46027 | G2: ='Posted Sales Invoice Lines'!L2 -> 28 | H2: ='Posted Sales Invoice Lines'!N2 -> 35 | I2: ='Posted Sales Invoice Lines'!O2 -> 980
A3: ='Posted Sales Invoice Lines'!A3 -> PS-INV173271 | B3: ='Posted Sales Invoice Lines'!B3 -> 10719-6 | C3: ='Posted Sales Invoice Lines'!C3 -> US Foods - Alcoa TN. | D3: ='Posted Sales Invoice Lines'!E3 -> F51136 | E3: ='Posted Sales Invoice Lines'!F3 -> Cs. Texas Toast 1" 12lvs | F3: ='Posted Sales Invoice Lines'!G3 -> 46027 | G3: ='Posted Sales Invoice Lines'!L3 -> 84 | H3: ='Posted Sales Invoice Lines'!N3 -> 40.12 | I3: ='Posted Sales Invoice Lines'!O3 -> 3370.08
A4: ='Posted Sales Invoice Lines'!A4 -> PS-INV173271 | B4: ='Posted Sales Invoice Lines'!B4 -> 10719-6 | C4: ='Posted Sales Invoice Lines'!C4 -> US Foods - Alcoa TN. | D4: ='Posted Sales Invoice Lines'!E4 -> F51004 | E4: ='Posted Sales Invoice Lines'!F4 -> Cs. Rye 5/8" 8lvs | F4: ='Posted Sales Invoice Lines'!G4 -> 46027 | G4: ='Posted Sales Invoice Lines'!L4 -> 8 | H4: ='Posted Sales Invoice Lines'!N4 -> 42.03 | I4: ='Posted Sales Invoice Lines'!O4 -> 336.24
A5: ='Posted Sales Invoice Lines'!A5 -> PS-INV173271 | B5: ='Posted Sales Invoice Lines'!B5 -> 10719-6 | C5: ='Posted Sales Invoice Lines'!C5 -> US Foods - Alcoa TN. | D5: ='Posted Sales Invoice Lines'!E5 -> F53025 | E5: ='Posted Sales Invoice Lines'!F5 -> Cs. Sesame Challah Kaiser 8-12pk | F5: ='Posted Sales Invoice Lines'!G5 -> 46027 | G5: ='Posted Sales Invoice Lines'!L5 -> 308 | H5: ='Posted Sales Invoice Lines'!N5 -> 39 | I5: ='Posted Sales Invoice Lines'!O5 -> 12012
A6: ='Posted Sales Invoice Lines'!A6 -> PS-INV173271 | B6: ='Posted Sales Invoice Lines'!B6 -> 10719-6 | C6: ='Posted Sales Invoice Lines'!C6 -> US Foods - Alcoa TN. | D6: ='Posted Sales Invoice Lines'!E6 -> F53087 | E6: ='Posted Sales Invoice Lines'!F6 -> Cs. 3.5" Challah Bun 8-12 pk | F6: ='Posted Sales Invoice Lines'!G6 -> 46027 | G6: ='Posted Sales Invoice Lines'!L6 -> 28 | H6: ='Posted Sales Invoice Lines'!N6 -> 36.24 | I6: ='Posted Sales Invoice Lines'!O6 -> 1014.72
A7: ='Posted Sales Invoice Lines'!A7 -> PS-INV173271 | B7: ='Posted Sales Invoice Lines'!B7 -> 10719-6 | C7: ='Posted Sales Invoice Lines'!C7 -> US Foods - Alcoa TN. | D7: ='Posted Sales Invoice Lines'!E7 -> F51066 | E7: ='Posted Sales Invoice Lines'!F7 -> Cs. Honey Wheat 3/4" 8lvs | F7: ='Posted Sales Invoice Lines'!G7 -> 46027 | G7: ='Posted Sales Invoice Lines'!L7 -> 14 | H7: ='Posted Sales Invoice Lines'!N7 -> 35.21 | I7: ='Posted Sales Invoice Lines'!O7 -> 492.94
A8: ='Posted Sales Invoice Lines'!A8 -> PS-INV173271 | B8: ='Posted Sales Invoice Lines'!B8 -> 10719-6 | C8: ='Posted Sales Invoice Lines'!C8 -> US Foods - Alcoa TN. | D8: ='Posted Sales Invoice Lines'!E8 -> F53001 | E8: ='Posted Sales Invoice Lines'!F8 -> Cs. 4" Brioche Bun 8-12pk | F8: ='Posted Sales Invoice Lines'!G8 -> 46027 | G8: ='Posted Sales Invoice Lines'!L8 -> 140 | H8: ='Posted Sales Invoice Lines'!N8 -> 45.49 | I8: ='Posted Sales Invoice Lines'!O8 -> 6368.6
A9: ='Posted Sales Invoice Lines'!A9 -> PS-INV173271 | B9: ='Posted Sales Invoice Lines'!B9 -> 10719-6 | C9: ='Posted Sales Invoice Lines'!C9 -> US Foods - Alcoa TN. | D9: ='Posted Sales Invoice Lines'!E9 -> F530501 | E9: ='Posted Sales Invoice Lines'!F9 -> Cs. 4.5" Challah Kaiser 6-12pk | F9: ='Posted Sales Invoice Lines'!G9 -> 46027 | G9: ='Posted Sales Invoice Lines'!L9 -> 28 | H9: ='Posted Sales Invoice Lines'!N9 -> 37.02 | I9: ='Posted Sales Invoice Lines'!O9 -> 1036.56
A10: ='Posted Sales Invoice Lines'!A10 -> PS-INV173271 | B10: ='Posted Sales Invoice Lines'!B10 -> 10719-6 | C10: ='Posted Sales Invoice Lines'!C10 -> US Foods - Alcoa TN. | D10: ='Posted Sales Invoice Lines'!E10 -> F51084 | E10: ='Posted Sales Invoice Lines'!F10 -> Cs. Wheatberry Hearth | F10: ='Posted Sales Invoice Lines'!G10 -> 46027 | G10: ='Posted Sales Invoice Lines'!L10 -> 4 | H10: ='Posted Sales Invoice Lines'!N10 -> 52.47 | I10: ='Posted Sales Invoice Lines'!O10 -> 209.88
A11: ='Posted Sales Invoice Lines'!A11 -> PS-INV173271 | B11: ='Posted Sales Invoice Lines'!B11 -> 10719-6 | C11: ='Posted Sales Invoice Lines'!C11 -> US Foods - Alcoa TN. | D11: ='Posted Sales Invoice Lines'!E11 -> F51024 | E11: ='Posted Sales Invoice Lines'!F11 -> Cs. Marble Rye 5/8" 8lvs | F11: ='Posted Sales Invoice Lines'!G11 -> 46027 | G11: ='Posted Sales Invoice Lines'!L11 -> 4 | H11: ='Posted Sales Invoice Lines'!N11 -> 54 | I11: ='Posted Sales Invoice Lines'!O11 -> 216
A12: ='Posted Sales Invoice Lines'!A12 -> PS-INV173271 | B12: ='Posted Sales Invoice Lines'!B12 -> 10719-6 | C12: ='Posted Sales Invoice Lines'!C12 -> US Foods - Alcoa TN. | D12: ='Posted Sales Invoice Lines'!E12 -> F51034 | E12: ='Posted Sales Invoice Lines'!F12 -> Cs. Sour Dough Hearth 5/8" 8lvs | F12: ='Posted Sales Invoice Lines'!G12 -> 46027 | G12: ='Posted Sales Invoice Lines'!L12 -> 8 | H12: ='Posted Sales Invoice Lines'!N12 -> 43.2 | I12: ='Posted Sales Invoice Lines'!O12 -> 345.6
A13: ='Posted Sales Invoice Lines'!A13 -> PS-INV173271 | B13: ='Posted Sales Invoice Lines'!B13 -> 10719-6 | C13: ='Posted Sales Invoice Lines'!C13 -> US Foods - Alcoa TN. | D13: ='Posted Sales Invoice Lines'!E13 -> F51157 | E13: ='Posted Sales Invoice Lines'!F13 -> Cs. Challah Hearth 7/8" 8lvs | F13: ='Posted Sales Invoice Lines'!G13 -> 46027 | G13: ='Posted Sales Invoice Lines'!L13 -> 28 | H13: ='Posted Sales Invoice Lines'!N13 -> 44.15 | I13: ='Posted Sales Invoice Lines'!O13 -> 1236.2
... A1891: ='Posted Sales Invoice Lines'!A1891 -> PS-INV231387 | B1891: ='Posted Sales Invoice Lines'!B1891 -> 1-4 | C1891: ='Posted Sales Invoice Lines'!C1891 -> Heath West | D1891: ='Posted Sales Invoice Lines'!E1891 -> F56251 | E1891: ='Posted Sales Invoice Lines'!F1891 -> Cs. Challah Sliders Sliced 18-12pks | F1891: ='Posted Sales Invoice Lines'!G1891 -> 46196 | G1891: ='Posted Sales Invoice Lines'!L1891 -> 1 | H1891: ='Posted Sales Invoice Lines'!N1891 -> 0 | I1891: ='Posted Sales Invoice Lines'!O1891 -> 0
